# Primeiramente tentará executar o try, caso ocorra alguma exceção ele executará o except
try:
    print(ola)
except:
    print('Erro')
    